Workbook

Sheet SessionLog
A1: SessionID | B1: Persona | C1: Round | D1: ItemType | E1: ItemName | F1: Role
A2: S001 | B2: A1 | C2: 1 | D2: Dataset | E2: SE_mysql.Users | F2: F
A3: S001 | B3: A1 | C3: 1 | D3: Dataset | E3: SE_mysql.Votes | F3: D
A4: S001 | B4: A1 | C4: 1 | D4: Attribute | E4: SE_mysql.Users.Reputation | F4: M
A5: S001 | B5: A1 | C5: 1 | D5: Attribute | E5: SE_mysql.Votes.VoteTypeId | F5: P
A6: S001 | B6: A1 | C6: 1 | D6: Attribute | E6: SE_mysql.Users.Id | F6: M
A7: S002 | B7: A1 | C7: 2 | D7: Dataset | E7: SE_mysql.Users | F7: F
A8: S002 | B8: A1 | C8: 2 | D8: Dataset | E8: SE_mysql.Votes | F8: D
A9: S002 | B9: A1 | C9: 2 | D9: Attribute | E9: SE_mysql.Users.Reputation | F9: M
A10: S002 | B10: A1 | C10: 2 | D10: Attribute | E10: SE_mysql.Users.UpVotes | F10: M
A11: S002 | B11: A1 | C11: 2 | D11: Attribute | E11: SE_mysql.Votes.CreationDate | F11: P
A12: S002 | B12: A1 | C12: 2 | D12: Attribute | E12: SE_mysql.Votes.VoteTypeId | F12: P
A13: S003 | B13: A1 | C13: 3 | D13: Dataset | E13: SE_mysql.Users | F13: F
... A309: S060 | B309: X2 | C309: 4 | D309: Attribute | E309: SE_mysql.Flagtypes.Name | F309: P

Sheet Datasets
A1: Analyste | B1: SE_mysql.postes (F) | C1: SE_mysql.postes (D) | D1: SE_mysql.Posttypes (F) | E1: SE_mysql.Posttypes (D) | F1: SE_mysql.Users (F) | G1: SE_mysql.Users (D) | H1: SE_mysql.Flagtypes (F) | I1: SE_mysql.Flagtypes (D) | J1: SE_mysql.Votes (F) | K1: SE_mysql.Votes (D) | L1: SE_mysql.Votetypes (F) | M1: SE_mysql.Votetypes (D) | N1: SE_mongodb.Badges (F) | O1: SE_mongodb.Badges (D) | P1: SE_mongodb.Posts (F) | Q1: SE_mongodb.Posts (D) | R1: SE_mongodb.Users (F) | S1: SE_mongodb.Users (D) | T1: SE_mongodb.Comments (F) | U1: SE_mongodb.Comments (D) | V1: SE_neo4j.postlinks (F) | W1: SE_neo4j.postlinks (D) | X1: SE_neo4j.Posts (F) | Y1: SE_neo4j.Posts (D) | Z1: SE_neo4j.Comments (F) | AA1: SE_neo4j.Comments (D) | AB1: SE_neo4j.Users (F) | AC1: SE_neo4j.Users (D) | AD1: SE_neo4j.Tags (F) | AE1: SE_neo4j.Tags (D)
A2: A1 | B2: =COUNTIFS(SessionLog!$B$2:$B$309,$A2,SessionLog!$E$2:$E$309,"SE_mysql.postes",SessionLog!$F$2:$F$309,"F") | C2: =COUNTIFS(SessionLog!$B$2:$B$309,$A2,SessionLog!$E$2:$E$309,"SE_mysql.postes",SessionLog!$F$2:$F$309,"D") | D2: =COUNTIFS(SessionLog!$B$2:$B$309,$A2,SessionLog!$E$2:$E$309,"SE_mysql.Posttypes",SessionLog!$F$2:$F$309,"F") | E2: =COUNTIFS(SessionLog!$B$2:$B$309,$A2,SessionLog!$E$2:$E$309,"SE_mysql.Posttypes",SessionLog!$F$2:$F$309,"D") | F2: =COUNTIFS(SessionLog!$B$2:$B$309,$A2,SessionLog!$E$2:$E$309,"SE_mysql.Users",SessionLog!$F$2:$F$309,"F") | G2: =COUNTIFS(SessionLog!$B$2:$B$309,$A2,SessionLog!$E$2:$E$309,"SE_mysql.Users",SessionLog!$F$2:$F$309,"D") | H2: =COUNTIFS(SessionLog!$B$2:$B$309,$A2,SessionLog!$E$2:$E$309,"SE_mysql.Flagtypes",SessionLog!$F$2:$F$309,"F") | I2: =COUNTIFS(SessionLog!$B$2:$B$309,$A2,SessionLog!$E$2:$E$309,"SE_mysql.Flagtypes",SessionLog!$F$2:$F$309,"D") | J2: =COUNTIFS(SessionLog!$B$2:$B$309,$A2,SessionLog!$E$2:$E$309,"SE_mysql.Votes",SessionLog!$F$2:$F$309,"F") | K2: =COUNTIFS(SessionLog!$B$2:$B$309,$A2,SessionLog!$E$2:$E$309,"SE_mysql.Votes",SessionLog!$F$2:$F$309,"D") | L2: =COUNTIFS(SessionLog!$B$2:$B$309,$A2,SessionLog!$E$2:$E$309,"SE_mysql.Votetypes",SessionLog!$F$2:$F$309,"F") | M2: =COUNTIFS(SessionLog!$B$2:$B$309,$A2,SessionLog!$E$2:$E$309,"SE_mysql.Votetypes",SessionLog!$F$2:$F$309,"D") | N2: =COUNTIFS(SessionLog!$B$2:$B$309,$A2,SessionLog!$E$2:$E$309,"SE_mongodb.Badges",SessionLog!$F$2:$F$309,"F") | O2: =COUNTIFS(SessionLog!$B$2:$B$309,$A2,SessionLog!$E$2:$E$309,"SE_mongodb.Badges",SessionLog!$F$2:$F$309,"D") | P2: =COUNTIFS(SessionLog!$B$2:$B$309,$A2,SessionLog!$E$2:$E$309,"SE_mongodb.Posts",SessionLog!$F$2:$F$309,"F") | Q2: =COUNTIFS(SessionLog!$B$2:$B$309,$A2,SessionLog!$E$2:$E$309,"SE_mongodb.Posts",SessionLog!$F$2:$F$309,"D") | R2: =COUNTIFS(SessionLog!$B$2:$B$309,$A2,SessionLog!$E$2:$E$309,"SE_mongodb.Users",SessionLog!$F$2:$F$309,"F") | S2: =COUNTIFS(SessionLog!$B$2:$B$309,$A2,SessionLog!$E$2:$E$309,"SE_mongodb.Users",SessionLog!$F$2:$F$309,"D") | T2: =COUNTIFS(SessionLog!$B$2:$B$309,$A2,SessionLog!$E$2:$E$309,"SE_mongodb.Comments",SessionLog!$F$2:$F$309,"F") | U2: =COUNTIFS(SessionLog!$B$2:$B$309,$A2,SessionLog!$E$2:$E$309,"SE_mongodb.Comments",SessionLog!$F$2:$F$309,"D") | V2: =COUNTIFS(SessionLog!$B$2:$B$309,$A2,SessionLog!$E$2:$E$309,"SE_neo4j.postlinks",SessionLog!$F$2:$F$309,"F") | W2: =COUNTIFS(SessionLog!$B$2:$B$309,$A2,SessionLog!$E$2:$E$309,"SE_neo4j.postlinks",SessionLog!$F$2:$F$309,"D") | X2: =COUNTIFS(SessionLog!$B$2:$B$309,$A2,SessionLog!$E$2:$E$309,"SE_neo4j.Posts",SessionLog!$F$2:$F$309,"F") | Y2: =COUNTIFS(SessionLog!$B$2:$B$309,$A2,SessionLog!$E$2:$E$309,"SE_neo4j.Posts",SessionLog!$F$2:$F$309,"D") | Z2: =COUNTIFS(SessionLog!$B$2:$B$309,$A2,SessionLog!$E$2:$E$309,"SE_neo4j.Comments",SessionLog!$F$2:$F$309,"F") | AA2: =COUNTIFS(SessionLog!$B$2:$B$309,$A2,SessionLog!$E$2:$E$309,"SE_neo4j.Comments",SessionLog!$F$2:$F$309,"D") | AB2: =COUNTIFS(SessionLog!$B$2:$B$309,$A2,SessionLog!$E$2:$E$309,"SE_neo4j.Users",SessionLog!$F$2:$F$309,"F") | AC2: =COUNTIFS(SessionLog!$B$2:$B$309,$A2,SessionLog!$E$2:$E$309,"SE_neo4j.Users",SessionLog!$F$2:$F$309,"D") | AD2: =COUNTIFS(SessionLog!$B$2:$B$309,$A2,SessionLog!$E$2:$E$309,"SE_neo4j.Tags",SessionLog!$F$2:$F$309,"F") | AE2: =COUNTIFS(SessionLog!$B$2:$B$309,$A2,SessionLog!$E$2:$E$309,"SE_neo4j.Tags",SessionLog!$F$2:$F$309,"D")
A3: A2 | B3: =COUNTIFS(SessionLog!$B$2:$B$309,$A3,SessionLog!$E$2:$E$309,"SE_mysql.postes",SessionLog!$F$2:$F$309,"F") | C3: =COUNTIFS(SessionLog!$B$2:$B$309,$A3,SessionLog!$E$2:$E$309,"SE_mysql.postes",SessionLog!$F$2:$F$309,"D") | D3: =COUNTIFS(SessionLog!$B$2:$B$309,$A3,SessionLog!$E$2:$E$309,"SE_mysql.Posttypes",SessionLog!$F$2:$F$309,"F") | E3: =COUNTIFS(SessionLog!$B$2:$B$309,$A3,SessionLog!$E$2:$E$309,"SE_mysql.Posttypes",SessionLog!$F$2:$F$309,"D") | F3: =COUNTIFS(SessionLog!$B$2:$B$309,$A3,SessionLog!$E$2:$E$309,"SE_mysql.Users",SessionLog!$F$2:$F$309,"F") | G3: =COUNTIFS(SessionLog!$B$2:$B$309,$A3,SessionLog!$E$2:$E$309,"SE_mysql.Users",SessionLog!$F$2:$F$309,"D") | H3: =COUNTIFS(SessionLog!$B$2:$B$309,$A3,SessionLog!$E$2:$E$309,"SE_mysql.Flagtypes",SessionLog!$F$2:$F$309,"F") | I3: =COUNTIFS(SessionLog!$B$2:$B$309,$A3,SessionLog!$E$2:$E$309,"SE_mysql.Flagtypes",SessionLog!$F$2:$F$309,"D") | J3: =COUNTIFS(SessionLog!$B$2:$B$309,$A3,SessionLog!$E$2:$E$309,"SE_mysql.Votes",SessionLog!$F$2:$F$309,"F") | K3: =COUNTIFS(SessionLog!$B$2:$B$309,$A3,SessionLog!$E$2:$E$309,"SE_mysql.Votes",SessionLog!$F$2:$F$309,"D") | L3: =COUNTIFS(SessionLog!$B$2:$B$309,$A3,SessionLog!$E$2:$E$309,"SE_mysql.Votetypes",SessionLog!$F$2:$F$309,"F") | M3: =COUNTIFS(SessionLog!$B$2:$B$309,$A3,SessionLog!$E$2:$E$309,"SE_mysql.Votetypes",SessionLog!$F$2:$F$309,"D") | N3: =COUNTIFS(SessionLog!$B$2:$B$309,$A3,SessionLog!$E$2:$E$309,"SE_mongodb.Badges",SessionLog!$F$2:$F$309,"F") | O3: =COUNTIFS(SessionLog!$B$2:$B$309,$A3,SessionLog!$E$2:$E$309,"SE_mongodb.Badges",SessionLog!$F$2:$F$309,"D") | P3: =COUNTIFS(SessionLog!$B$2:$B$309,$A3,SessionLog!$E$2:$E$309,"SE_mongodb.Posts",SessionLog!$F$2:$F$309,"F") | Q3: =COUNTIFS(SessionLog!$B$2:$B$309,$A3,SessionLog!$E$2:$E$309,"SE_mongodb.Posts",SessionLog!$F$2:$F$309,"D") | R3: =COUNTIFS(SessionLog!$B$2:$B$309,$A3,SessionLog!$E$2:$E$309,"SE_mongodb.Users",SessionLog!$F$2:$F$309,"F") | S3: =COUNTIFS(SessionLog!$B$2:$B$309,$A3,SessionLog!$E$2:$E$309,"SE_mongodb.Users",SessionLog!$F$2:$F$309,"D") | T3: =COUNTIFS(SessionLog!$B$2:$B$309,$A3,SessionLog!$E$2:$E$309,"SE_mongodb.Comments",SessionLog!$F$2:$F$309,"F") | U3: =COUNTIFS(SessionLog!$B$2:$B$309,$A3,SessionLog!$E$2:$E$309,"SE_mongodb.Comments",SessionLog!$F$2:$F$309,"D") | V3: =COUNTIFS(SessionLog!$B$2:$B$309,$A3,SessionLog!$E$2:$E$309,"SE_neo4j.postlinks",SessionLog!$F$2:$F$309,"F") | W3: =COUNTIFS(SessionLog!$B$2:$B$309,$A3,SessionLog!$E$2:$E$309,"SE_neo4j.postlinks",SessionLog!$F$2:$F$309,"D") | X3: =COUNTIFS(SessionLog!$B$2:$B$309,$A3,SessionLog!$E$2:$E$309,"SE_neo4j.Posts",SessionLog!$F$2:$F$309,"F") | Y3: =COUNTIFS(SessionLog!$B$2:$B$309,$A3,SessionLog!$E$2:$E$309,"SE_neo4j.Posts",SessionLog!$F$2:$F$309,"D") | Z3: =COUNTIFS(SessionLog!$B$2:$B$309,$A3,SessionLog!$E$2:$E$309,"SE_neo4j.Comments",SessionLog!$F$2:$F$309,"F") | AA3: =COUNTIFS(SessionLog!$B$2:$B$309,$A3,SessionLog!$E$2:$E$309,"SE_neo4j.Comments",SessionLog!$F$2:$F$309,"D") | AB3: =COUNTIFS(SessionLog!$B$2:$B$309,$A3,SessionLog!$E$2:$E$309,"SE_neo4j.Users",SessionLog!$F$2:$F$309,"F") | AC3: =COUNTIFS(SessionLog!$B$2:$B$309,$A3,SessionLog!$E$2:$E$309,"SE_neo4j.Users",SessionLog!$F$2:$F$309,"D") | AD3: =COUNTIFS(SessionLog!$B$2:$B$309,$A3,SessionLog!$E$2:$E$309,"SE_neo4j.Tags",SessionLog!$F$2:$F$309,"F") | AE3: =COUNTIFS(SessionLog!$B$2:$B$309,$A3,SessionLog!$E$2:$E$309,"SE_neo4j.Tags",SessionLog!$F$2:$F$309,"D")
A4: A3 | B4: =COUNTIFS(SessionLog!$B$2:$B$309,$A4,SessionLog!$E$2:$E$309,"SE_mysql.postes",SessionLog!$F$2:$F$309,"F") | C4: =COUNTIFS(SessionLog!$B$2:$B$309,$A4,SessionLog!$E$2:$E$309,"SE_mysql.postes",SessionLog!$F$2:$F$309,"D") | D4: =COUNTIFS(SessionLog!$B$2:$B$309,$A4,SessionLog!$E$2:$E$309,"SE_mysql.Posttypes",SessionLog!$F$2:$F$309,"F") | E4: =COUNTIFS(SessionLog!$B$2:$B$309,$A4,SessionLog!$E$2:$E$309,"SE_mysql.Posttypes",SessionLog!$F$2:$F$309,"D") | F4: =COUNTIFS(SessionLog!$B$2:$B$309,$A4,SessionLog!$E$2:$E$309,"SE_mysql.Users",SessionLog!$F$2:$F$309,"F") | G4: =COUNTIFS(SessionLog!$B$2:$B$309,$A4,SessionLog!$E$2:$E$309,"SE_mysql.Users",SessionLog!$F$2:$F$309,"D") | H4: =COUNTIFS(SessionLog!$B$2:$B$309,$A4,SessionLog!$E$2:$E$309,"SE_mysql.Flagtypes",SessionLog!$F$2:$F$309,"F") | I4: =COUNTIFS(SessionLog!$B$2:$B$309,$A4,SessionLog!$E$2:$E$309,"SE_mysql.Flagtypes",SessionLog!$F$2:$F$309,"D") | J4: =COUNTIFS(SessionLog!$B$2:$B$309,$A4,SessionLog!$E$2:$E$309,"SE_mysql.Votes",SessionLog!$F$2:$F$309,"F") | K4: =COUNTIFS(SessionLog!$B$2:$B$309,$A4,SessionLog!$E$2:$E$309,"SE_mysql.Votes",SessionLog!$F$2:$F$309,"D") | L4: =COUNTIFS(SessionLog!$B$2:$B$309,$A4,SessionLog!$E$2:$E$309,"SE_mysql.Votetypes",SessionLog!$F$2:$F$309,"F") | M4: =COUNTIFS(SessionLog!$B$2:$B$309,$A4,SessionLog!$E$2:$E$309,"SE_mysql.Votetypes",SessionLog!$F$2:$F$309,"D") | N4: =COUNTIFS(SessionLog!$B$2:$B$309,$A4,SessionLog!$E$2:$E$309,"SE_mongodb.Badges",SessionLog!$F$2:$F$309,"F") | O4: =COUNTIFS(SessionLog!$B$2:$B$309,$A4,SessionLog!$E$2:$E$309,"SE_mongodb.Badges",SessionLog!$F$2:$F$309,"D") | P4: =COUNTIFS(SessionLog!$B$2:$B$309,$A4,SessionLog!$E$2:$E$309,"SE_mongodb.Posts",SessionLog!$F$2:$F$309,"F") | Q4: =COUNTIFS(SessionLog!$B$2:$B$309,$A4,SessionLog!$E$2:$E$309,"SE_mongodb.Posts",SessionLog!$F$2:$F$309,"D") | R4: =COUNTIFS(SessionLog!$B$2:$B$309,$A4,SessionLog!$E$2:$E$309,"SE_mongodb.Users",SessionLog!$F$2:$F$309,"F") | S4: =COUNTIFS(SessionLog!$B$2:$B$309,$A4,SessionLog!$E$2:$E$309,"SE_mongodb.Users",SessionLog!$F$2:$F$309,"D") | T4: =COUNTIFS(SessionLog!$B$2:$B$309,$A4,SessionLog!$E$2:$E$309,"SE_mongodb.Comments",SessionLog!$F$2:$F$309,"F") | U4: =COUNTIFS(SessionLog!$B$2:$B$309,$A4,SessionLog!$E$2:$E$309,"SE_mongodb.Comments",SessionLog!$F$2:$F$309,"D") | V4: =COUNTIFS(SessionLog!$B$2:$B$309,$A4,SessionLog!$E$2:$E$309,"SE_neo4j.postlinks",SessionLog!$F$2:$F$309,"F") | W4: =COUNTIFS(SessionLog!$B$2:$B$309,$A4,SessionLog!$E$2:$E$309,"SE_neo4j.postlinks",SessionLog!$F$2:$F$309,"D") | X4: =COUNTIFS(SessionLog!$B$2:$B$309,$A4,SessionLog!$E$2:$E$309,"SE_neo4j.Posts",SessionLog!$F$2:$F$309,"F") | Y4: =COUNTIFS(SessionLog!$B$2:$B$309,$A4,SessionLog!$E$2:$E$309,"SE_neo4j.Posts",SessionLog!$F$2:$F$309,"D") | Z4: =COUNTIFS(SessionLog!$B$2:$B$309,$A4,SessionLog!$E$2:$E$309,"SE_neo4j.Comments",SessionLog!$F$2:$F$309,"F") | AA4: =COUNTIFS(SessionLog!$B$2:$B$309,$A4,SessionLog!$E$2:$E$309,"SE_neo4j.Comments",SessionLog!$F$2:$F$309,"D") | AB4: =COUNTIFS(SessionLog!$B$2:$B$309,$A4,SessionLog!$E$2:$E$309,"SE_neo4j.Users",SessionLog!$F$2:$F$309,"F") | AC4: =COUNTIFS(SessionLog!$B$2:$B$309,$A4,SessionLog!$E$2:$E$309,"SE_neo4j.Users",SessionLog!$F$2:$F$309,"D") | AD4: =COUNTIFS(SessionLog!$B$2:$B$309,$A4,SessionLog!$E$2:$E$309,"SE_neo4j.Tags",SessionLog!$F$2:$F$309,"F") | AE4: =COUNTIFS(SessionLog!$B$2:$B$309,$A4,SessionLog!$E$2:$E$309,"SE_neo4j.Tags",SessionLog!$F$2:$F$309,"D")
A5: B1 | B5: =COUNTIFS(SessionLog!$B$2:$B$309,$A5,SessionLog!$E$2:$E$309,"SE_mysql.postes",SessionLog!$F$2:$F$309,"F") | C5: =COUNTIFS(SessionLog!$B$2:$B$309,$A5,SessionLog!$E$2:$E$309,"SE_mysql.postes",SessionLog!$F$2:$F$309,"D") | D5: =COUNTIFS(SessionLog!$B$2:$B$309,$A5,SessionLog!$E$2:$E$309,"SE_mysql.Posttypes",SessionLog!$F$2:$F$309,"F") | E5: =COUNTIFS(SessionLog!$B$2:$B$309,$A5,SessionLog!$E$2:$E$309,"SE_mysql.Posttypes",SessionLog!$F$2:$F$309,"D") | F5: =COUNTIFS(SessionLog!$B$2:$B$309,$A5,SessionLog!$E$2:$E$309,"SE_mysql.Users",SessionLog!$F$2:$F$309,"F") | G5: =COUNTIFS(SessionLog!$B$2:$B$309,$A5,SessionLog!$E$2:$E$309,"SE_mysql.Users",SessionLog!$F$2:$F$309,"D") | H5: =COUNTIFS(SessionLog!$B$2:$B$309,$A5,SessionLog!$E$2:$E$309,"SE_mysql.Flagtypes",SessionLog!$F$2:$F$309,"F") | I5: =COUNTIFS(SessionLog!$B$2:$B$309,$A5,SessionLog!$E$2:$E$309,"SE_mysql.Flagtypes",SessionLog!$F$2:$F$309,"D") | J5: =COUNTIFS(SessionLog!$B$2:$B$309,$A5,SessionLog!$E$2:$E$309,"SE_mysql.Votes",SessionLog!$F$2:$F$309,"F") | K5: =COUNTIFS(SessionLog!$B$2:$B$309,$A5,SessionLog!$E$2:$E$309,"SE_mysql.Votes",SessionLog!$F$2:$F$309,"D") | L5: =COUNTIFS(SessionLog!$B$2:$B$309,$A5,SessionLog!$E$2:$E$309,"SE_mysql.Votetypes",SessionLog!$F$2:$F$309,"F") | M5: =COUNTIFS(SessionLog!$B$2:$B$309,$A5,SessionLog!$E$2:$E$309,"SE_mysql.Votetypes",SessionLog!$F$2:$F$309,"D") | N5: =COUNTIFS(SessionLog!$B$2:$B$309,$A5,SessionLog!$E$2:$E$309,"SE_mongodb.Badges",SessionLog!$F$2:$F$309,"F") | O5: =COUNTIFS(SessionLog!$B$2:$B$309,$A5,SessionLog!$E$2:$E$309,"SE_mongodb.Badges",SessionLog!$F$2:$F$309,"D") | P5: =COUNTIFS(SessionLog!$B$2:$B$309,$A5,SessionLog!$E$2:$E$309,"SE_mongodb.Posts",SessionLog!$F$2:$F$309,"F") | Q5: =COUNTIFS(SessionLog!$B$2:$B$309,$A5,SessionLog!$E$2:$E$309,"SE_mongodb.Posts",SessionLog!$F$2:$F$309,"D") | R5: =COUNTIFS(SessionLog!$B$2:$B$309,$A5,SessionLog!$E$2:$E$309,"SE_mongodb.Users",SessionLog!$F$2:$F$309,"F") | S5: =COUNTIFS(SessionLog!$B$2:$B$309,$A5,SessionLog!$E$2:$E$309,"SE_mongodb.Users",SessionLog!$F$2:$F$309,"D") | T5: =COUNTIFS(SessionLog!$B$2:$B$309,$A5,SessionLog!$E$2:$E$309,"SE_mongodb.Comments",SessionLog!$F$2:$F$309,"F") | U5: =COUNTIFS(SessionLog!$B$2:$B$309,$A5,SessionLog!$E$2:$E$309,"SE_mongodb.Comments",SessionLog!$F$2:$F$309,"D") | V5: =COUNTIFS(SessionLog!$B$2:$B$309,$A5,SessionLog!$E$2:$E$309,"SE_neo4j.postlinks",SessionLog!$F$2:$F$309,"F") | W5: =COUNTIFS(SessionLog!$B$2:$B$309,$A5,SessionLog!$E$2:$E$309,"SE_neo4j.postlinks",SessionLog!$F$2:$F$309,"D") | X5: =COUNTIFS(SessionLog!$B$2:$B$309,$A5,SessionLog!$E$2:$E$309,"SE_neo4j.Posts",SessionLog!$F$2:$F$309,"F") | Y5: =COUNTIFS(SessionLog!$B$2:$B$309,$A5,SessionLog!$E$2:$E$309,"SE_neo4j.Posts",SessionLog!$F$2:$F$309,"D") | Z5: =COUNTIFS(SessionLog!$B$2:$B$309,$A5,SessionLog!$E$2:$E$309,"SE_neo4j.Comments",SessionLog!$F$2:$F$309,"F") | AA5: =COUNTIFS(SessionLog!$B$2:$B$309,$A5,SessionLog!$E$2:$E$309,"SE_neo4j.Comments",SessionLog!$F$2:$F$309,"D") | AB5: =COUNTIFS(SessionLog!$B$2:$B$309,$A5,SessionLog!$E$2:$E$309,"SE_neo4j.Users",SessionLog!$F$2:$F$309,"F") | AC5: =COUNTIFS(SessionLog!$B$2:$B$309,$A5,SessionLog!$E$2:$E$309,"SE_neo4j.Users",SessionLog!$F$2:$F$309,"D") | AD5: =COUNTIFS(SessionLog!$B$2:$B$309,$A5,SessionLog!$E$2:$E$309,"SE_neo4j.Tags",SessionLog!$F$2:$F$309,"F") | AE5: =COUNTIFS(SessionLog!$B$2:$B$309,$A5,SessionLog!$E$2:$E$309,"SE_neo4j.Tags",SessionLog!$F$2:$F$309,"D")
A6: B2 | B6: =COUNTIFS(SessionLog!$B$2:$B$309,$A6,SessionLog!$E$2:$E$309,"SE_mysql.postes",SessionLog!$F$2:$F$309,"F") | C6: =COUNTIFS(SessionLog!$B$2:$B$309,$A6,SessionLog!$E$2:$E$309,"SE_mysql.postes",SessionLog!$F$2:$F$309,"D") | D6: =COUNTIFS(SessionLog!$B$2:$B$309,$A6,SessionLog!$E$2:$E$309,"SE_mysql.Posttypes",SessionLog!$F$2:$F$309,"F") | E6: =COUNTIFS(SessionLog!$B$2:$B$309,$A6,SessionLog!$E$2:$E$309,"SE_mysql.Posttypes",SessionLog!$F$2:$F$309,"D") | F6: =COUNTIFS(SessionLog!$B$2:$B$309,$A6,SessionLog!$E$2:$E$309,"SE_mysql.Users",SessionLog!$F$2:$F$309,"F") | G6: =COUNTIFS(SessionLog!$B$2:$B$309,$A6,SessionLog!$E$2:$E$309,"SE_mysql.Users",SessionLog!$F$2:$F$309,"D") | H6: =COUNTIFS(SessionLog!$B$2:$B$309,$A6,SessionLog!$E$2:$E$309,"SE_mysql.Flagtypes",SessionLog!$F$2:$F$309,"F") | I6: =COUNTIFS(SessionLog!$B$2:$B$309,$A6,SessionLog!$E$2:$E$309,"SE_mysql.Flagtypes",SessionLog!$F$2:$F$309,"D") | J6: =COUNTIFS(SessionLog!$B$2:$B$309,$A6,SessionLog!$E$2:$E$309,"SE_mysql.Votes",SessionLog!$F$2:$F$309,"F") | K6: =COUNTIFS(SessionLog!$B$2:$B$309,$A6,SessionLog!$E$2:$E$309,"SE_mysql.Votes",SessionLog!$F$2:$F$309,"D") | L6: =COUNTIFS(SessionLog!$B$2:$B$309,$A6,SessionLog!$E$2:$E$309,"SE_mysql.Votetypes",SessionLog!$F$2:$F$309,"F") | M6: =COUNTIFS(SessionLog!$B$2:$B$309,$A6,SessionLog!$E$2:$E$309,"SE_mysql.Votetypes",SessionLog!$F$2:$F$309,"D") | N6: =COUNTIFS(SessionLog!$B$2:$B$309,$A6,SessionLog!$E$2:$E$309,"SE_mongodb.Badges",SessionLog!$F$2:$F$309,"F") | O6: =COUNTIFS(SessionLog!$B$2:$B$309,$A6,SessionLog!$E$2:$E$309,"SE_mongodb.Badges",SessionLog!$F$2:$F$309,"D") | P6: =COUNTIFS(SessionLog!$B$2:$B$309,$A6,SessionLog!$E$2:$E$309,"SE_mongodb.Posts",SessionLog!$F$2:$F$309,"F") | Q6: =COUNTIFS(SessionLog!$B$2:$B$309,$A6,SessionLog!$E$2:$E$309,"SE_mongodb.Posts",SessionLog!$F$2:$F$309,"D") | R6: =COUNTIFS(SessionLog!$B$2:$B$309,$A6,SessionLog!$E$2:$E$309,"SE_mongodb.Users",SessionLog!$F$2:$F$309,"F") | S6: =COUNTIFS(SessionLog!$B$2:$B$309,$A6,SessionLog!$E$2:$E$309,"SE_mongodb.Users",SessionLog!$F$2:$F$309,"D") | T6: =COUNTIFS(SessionLog!$B$2:$B$309,$A6,SessionLog!$E$2:$E$309,"SE_mongodb.Comments",SessionLog!$F$2:$F$309,"F") | U6: =COUNTIFS(SessionLog!$B$2:$B$309,$A6,SessionLog!$E$2:$E$309,"SE_mongodb.Comments",SessionLog!$F$2:$F$309,"D") | V6: =COUNTIFS(SessionLog!$B$2:$B$309,$A6,SessionLog!$E$2:$E$309,"SE_neo4j.postlinks",SessionLog!$F$2:$F$309,"F") | W6: =COUNTIFS(SessionLog!$B$2:$B$309,$A6,SessionLog!$E$2:$E$309,"SE_neo4j.postlinks",SessionLog!$F$2:$F$309,"D") | X6: =COUNTIFS(SessionLog!$B$2:$B$309,$A6,SessionLog!$E$2:$E$309,"SE_neo4j.Posts",SessionLog!$F$2:$F$309,"F") | Y6: =COUNTIFS(SessionLog!$B$2:$B$309,$A6,SessionLog!$E$2:$E$309,"SE_neo4j.Posts",SessionLog!$F$2:$F$309,"D") | Z6: =COUNTIFS(SessionLog!$B$2:$B$309,$A6,SessionLog!$E$2:$E$309,"SE_neo4j.Comments",SessionLog!$F$2:$F$309,"F") | AA6: =COUNTIFS(SessionLog!$B$2:$B$309,$A6,SessionLog!$E$2:$E$309,"SE_neo4j.Comments",SessionLog!$F$2:$F$309,"D") | AB6: =COUNTIFS(SessionLog!$B$2:$B$309,$A6,SessionLog!$E$2:$E$309,"SE_neo4j.Users",SessionLog!$F$2:$F$309,"F") | AC6: =COUNTIFS(SessionLog!$B$2:$B$309,$A6,SessionLog!$E$2:$E$309,"SE_neo4j.Users",SessionLog!$F$2:$F$309,"D") | AD6: =COUNTIFS(SessionLog!$B$2:$B$309,$A6,SessionLog!$E$2:$E$309,"SE_neo4j.Tags",SessionLog!$F$2:$F$309,"F") | AE6: =COUNTIFS(SessionLog!$B$2:$B$309,$A6,SessionLog!$E$2:$E$309,"SE_neo4j.Tags",SessionLog!$F$2:$F$309,"D")
A7: B3 | B7: =COUNTIFS(SessionLog!$B$2:$B$309,$A7,SessionLog!$E$2:$E$309,"SE_mysql.postes",SessionLog!$F$2:$F$309,"F") | C7: =COUNTIFS(SessionLog!$B$2:$B$309,$A7,SessionLog!$E$2:$E$309,"SE_mysql.postes",SessionLog!$F$2:$F$309,"D") | D7: =COUNTIFS(SessionLog!$B$2:$B$309,$A7,SessionLog!$E$2:$E$309,"SE_mysql.Posttypes",SessionLog!$F$2:$F$309,"F") | E7: =COUNTIFS(SessionLog!$B$2:$B$309,$A7,SessionLog!$E$2:$E$309,"SE_mysql.Posttypes",SessionLog!$F$2:$F$309,"D") | F7: =COUNTIFS(SessionLog!$B$2:$B$309,$A7,SessionLog!$E$2:$E$309,"SE_mysql.Users",SessionLog!$F$2:$F$309,"F") | G7: =COUNTIFS(SessionLog!$B$2:$B$309,$A7,SessionLog!$E$2:$E$309,"SE_mysql.Users",SessionLog!$F$2:$F$309,"D") | H7: =COUNTIFS(SessionLog!$B$2:$B$309,$A7,SessionLog!$E$2:$E$309,"SE_mysql.Flagtypes",SessionLog!$F$2:$F$309,"F") | I7: =COUNTIFS(SessionLog!$B$2:$B$309,$A7,SessionLog!$E$2:$E$309,"SE_mysql.Flagtypes",SessionLog!$F$2:$F$309,"D") | J7: =COUNTIFS(SessionLog!$B$2:$B$309,$A7,SessionLog!$E$2:$E$309,"SE_mysql.Votes",SessionLog!$F$2:$F$309,"F") | K7: =COUNTIFS(SessionLog!$B$2:$B$309,$A7,SessionLog!$E$2:$E$309,"SE_mysql.Votes",SessionLog!$F$2:$F$309,"D") | L7: =COUNTIFS(SessionLog!$B$2:$B$309,$A7,SessionLog!$E$2:$E$309,"SE_mysql.Votetypes",SessionLog!$F$2:$F$309,"F") | M7: =COUNTIFS(SessionLog!$B$2:$B$309,$A7,SessionLog!$E$2:$E$309,"SE_mysql.Votetypes",SessionLog!$F$2:$F$309,"D") | N7: =COUNTIFS(SessionLog!$B$2:$B$309,$A7,SessionLog!$E$2:$E$309,"SE_mongodb.Badges",SessionLog!$F$2:$F$309,"F") | O7: =COUNTIFS(SessionLog!$B$2:$B$309,$A7,SessionLog!$E$2:$E$309,"SE_mongodb.Badges",SessionLog!$F$2:$F$309,"D") | P7: =COUNTIFS(SessionLog!$B$2:$B$309,$A7,SessionLog!$E$2:$E$309,"SE_mongodb.Posts",SessionLog!$F$2:$F$309,"F") | Q7: =COUNTIFS(SessionLog!$B$2:$B$309,$A7,SessionLog!$E$2:$E$309,"SE_mongodb.Posts",SessionLog!$F$2:$F$309,"D") | R7: =COUNTIFS(SessionLog!$B$2:$B$309,$A7,SessionLog!$E$2:$E$309,"SE_mongodb.Users",SessionLog!$F$2:$F$309,"F") | S7: =COUNTIFS(SessionLog!$B$2:$B$309,$A7,SessionLog!$E$2:$E$309,"SE_mongodb.Users",SessionLog!$F$2:$F$309,"D") | T7: =COUNTIFS(SessionLog!$B$2:$B$309,$A7,SessionLog!$E$2:$E$309,"SE_mongodb.Comments",SessionLog!$F$2:$F$309,"F") | U7: =COUNTIFS(SessionLog!$B$2:$B$309,$A7,SessionLog!$E$2:$E$309,"SE_mongodb.Comments",SessionLog!$F$2:$F$309,"D") | V7: =COUNTIFS(SessionLog!$B$2:$B$309,$A7,SessionLog!$E$2:$E$309,"SE_neo4j.postlinks",SessionLog!$F$2:$F$309,"F") | W7: =COUNTIFS(SessionLog!$B$2:$B$309,$A7,SessionLog!$E$2:$E$309,"SE_neo4j.postlinks",SessionLog!$F$2:$F$309,"D") | X7: =COUNTIFS(SessionLog!$B$2:$B$309,$A7,SessionLog!$E$2:$E$309,"SE_neo4j.Posts",SessionLog!$F$2:$F$309,"F") | Y7: =COUNTIFS(SessionLog!$B$2:$B$309,$A7,SessionLog!$E$2:$E$309,"SE_neo4j.Posts",SessionLog!$F$2:$F$309,"D") | Z7: =COUNTIFS(SessionLog!$B$2:$B$309,$A7,SessionLog!$E$2:$E$309,"SE_neo4j.Comments",SessionLog!$F$2:$F$309,"F") | AA7: =COUNTIFS(SessionLog!$B$2:$B$309,$A7,SessionLog!$E$2:$E$309,"SE_neo4j.Comments",SessionLog!$F$2:$F$309,"D") | AB7: =COUNTIFS(SessionLog!$B$2:$B$309,$A7,SessionLog!$E$2:$E$309,"SE_neo4j.Users",SessionLog!$F$2:$F$309,"F") | AC7: =COUNTIFS(SessionLog!$B$2:$B$309,$A7,SessionLog!$E$2:$E$309,"SE_neo4j.Users",SessionLog!$F$2:$F$309,"D") | AD7: =COUNTIFS(SessionLog!$B$2:$B$309,$A7,SessionLog!$E$2:$E$309,"SE_neo4j.Tags",SessionLog!$F$2:$F$309,"F") | AE7: =COUNTIFS(SessionLog!$B$2:$B$309,$A7,SessionLog!$E$2:$E$309,"SE_neo4j.Tags",SessionLog!$F$2:$F$309,"D")
A8: C1 | B8: =COUNTIFS(SessionLog!$B$2:$B$309,$A8,SessionLog!$E$2:$E$309,"SE_mysql.postes",SessionLog!$F$2:$F$309,"F") | C8: =COUNTIFS(SessionLog!$B$2:$B$309,$A8,SessionLog!$E$2:$E$309,"SE_mysql.postes",SessionLog!$F$2:$F$309,"D") | D8: =COUNTIFS(SessionLog!$B$2:$B$309,$A8,SessionLog!$E$2:$E$309,"SE_mysql.Posttypes",SessionLog!$F$2:$F$309,"F") | E8: =COUNTIFS(SessionLog!$B$2:$B$309,$A8,SessionLog!$E$2:$E$309,"SE_mysql.Posttypes",SessionLog!$F$2:$F$309,"D") | F8: =COUNTIFS(SessionLog!$B$2:$B$309,$A8,SessionLog!$E$2:$E$309,"SE_mysql.Users",SessionLog!$F$2:$F$309,"F") | G8: =COUNTIFS(SessionLog!$B$2:$B$309,$A8,SessionLog!$E$2:$E$309,"SE_mysql.Users",SessionLog!$F$2:$F$309,"D") | H8: =COUNTIFS(SessionLog!$B$2:$B$309,$A8,SessionLog!$E$2:$E$309,"SE_mysql.Flagtypes",SessionLog!$F$2:$F$309,"F") | I8: =COUNTIFS(SessionLog!$B$2:$B$309,$A8,SessionLog!$E$2:$E$309,"SE_mysql.Flagtypes",SessionLog!$F$2:$F$309,"D") | J8: =COUNTIFS(SessionLog!$B$2:$B$309,$A8,SessionLog!$E$2:$E$309,"SE_mysql.Votes",SessionLog!$F$2:$F$309,"F") | K8: =COUNTIFS(SessionLog!$B$2:$B$309,$A8,SessionLog!$E$2:$E$309,"SE_mysql.Votes",SessionLog!$F$2:$F$309,"D") | L8: =COUNTIFS(SessionLog!$B$2:$B$309,$A8,SessionLog!$E$2:$E$309,"SE_mysql.Votetypes",SessionLog!$F$2:$F$309,"F") | M8: =COUNTIFS(SessionLog!$B$2:$B$309,$A8,SessionLog!$E$2:$E$309,"SE_mysql.Votetypes",SessionLog!$F$2:$F$309,"D") | N8: =COUNTIFS(SessionLog!$B$2:$B$309,$A8,SessionLog!$E$2:$E$309,"SE_mongodb.Badges",SessionLog!$F$2:$F$309,"F") | O8: =COUNTIFS(SessionLog!$B$2:$B$309,$A8,SessionLog!$E$2:$E$309,"SE_mongodb.Badges",SessionLog!$F$2:$F$309,"D") | P8: =COUNTIFS(SessionLog!$B$2:$B$309,$A8,SessionLog!$E$2:$E$309,"SE_mongodb.Posts",SessionLog!$F$2:$F$309,"F") | Q8: =COUNTIFS(SessionLog!$B$2:$B$309,$A8,SessionLog!$E$2:$E$309,"SE_mongodb.Posts",SessionLog!$F$2:$F$309,"D") | R8: =COUNTIFS(SessionLog!$B$2:$B$309,$A8,SessionLog!$E$2:$E$309,"SE_mongodb.Users",SessionLog!$F$2:$F$309,"F") | S8: =COUNTIFS(SessionLog!$B$2:$B$309,$A8,SessionLog!$E$2:$E$309,"SE_mongodb.Users",SessionLog!$F$2:$F$309,"D") | T8: =COUNTIFS(SessionLog!$B$2:$B$309,$A8,SessionLog!$E$2:$E$309,"SE_mongodb.Comments",SessionLog!$F$2:$F$309,"F") | U8: =COUNTIFS(SessionLog!$B$2:$B$309,$A8,SessionLog!$E$2:$E$309,"SE_mongodb.Comments",SessionLog!$F$2:$F$309,"D") | V8: =COUNTIFS(SessionLog!$B$2:$B$309,$A8,SessionLog!$E$2:$E$309,"SE_neo4j.postlinks",SessionLog!$F$2:$F$309,"F") | W8: =COUNTIFS(SessionLog!$B$2:$B$309,$A8,SessionLog!$E$2:$E$309,"SE_neo4j.postlinks",SessionLog!$F$2:$F$309,"D") | X8: =COUNTIFS(SessionLog!$B$2:$B$309,$A8,SessionLog!$E$2:$E$309,"SE_neo4j.Posts",SessionLog!$F$2:$F$309,"F") | Y8: =COUNTIFS(SessionLog!$B$2:$B$309,$A8,SessionLog!$E$2:$E$309,"SE_neo4j.Posts",SessionLog!$F$2:$F$309,"D") | Z8: =COUNTIFS(SessionLog!$B$2:$B$309,$A8,SessionLog!$E$2:$E$309,"SE_neo4j.Comments",SessionLog!$F$2:$F$309,"F") | AA8: =COUNTIFS(SessionLog!$B$2:$B$309,$A8,SessionLog!$E$2:$E$309,"SE_neo4j.Comments",SessionLog!$F$2:$F$309,"D") | AB8: =COUNTIFS(SessionLog!$B$2:$B$309,$A8,SessionLog!$E$2:$E$309,"SE_neo4j.Users",SessionLog!$F$2:$F$309,"F") | AC8: =COUNTIFS(SessionLog!$B$2:$B$309,$A8,SessionLog!$E$2:$E$309,"SE_neo4j.Users",SessionLog!$F$2:$F$309,"D") | AD8: =COUNTIFS(SessionLog!$B$2:$B$309,$A8,SessionLog!$E$2:$E$309,"SE_neo4j.Tags",SessionLog!$F$2:$F$309,"F") | AE8: =COUNTIFS(SessionLog!$B$2:$B$309,$A8,SessionLog!$E$2:$E$309,"SE_neo4j.Tags",SessionLog!$F$2:$F$309,"D")
A9: C2 | B9: =COUNTIFS(SessionLog!$B$2:$B$309,$A9,SessionLog!$E$2:$E$309,"SE_mysql.postes",SessionLog!$F$2:$F$309,"F") | C9: =COUNTIFS(SessionLog!$B$2:$B$309,$A9,SessionLog!$E$2:$E$309,"SE_mysql.postes",SessionLog!$F$2:$F$309,"D") | D9: =COUNTIFS(SessionLog!$B$2:$B$309,$A9,SessionLog!$E$2:$E$309,"SE_mysql.Posttypes",SessionLog!$F$2:$F$309,"F") | E9: =COUNTIFS(SessionLog!$B$2:$B$309,$A9,SessionLog!$E$2:$E$309,"SE_mysql.Posttypes",SessionLog!$F$2:$F$309,"D") | F9: =COUNTIFS(SessionLog!$B$2:$B$309,$A9,SessionLog!$E$2:$E$309,"SE_mysql.Users",SessionLog!$F$2:$F$309,"F") | G9: =COUNTIFS(SessionLog!$B$2:$B$309,$A9,SessionLog!$E$2:$E$309,"SE_mysql.Users",SessionLog!$F$2:$F$309,"D") | H9: =COUNTIFS(SessionLog!$B$2:$B$309,$A9,SessionLog!$E$2:$E$309,"SE_mysql.Flagtypes",SessionLog!$F$2:$F$309,"F") | I9: =COUNTIFS(SessionLog!$B$2:$B$309,$A9,SessionLog!$E$2:$E$309,"SE_mysql.Flagtypes",SessionLog!$F$2:$F$309,"D") | J9: =COUNTIFS(SessionLog!$B$2:$B$309,$A9,SessionLog!$E$2:$E$309,"SE_mysql.Votes",SessionLog!$F$2:$F$309,"F") | K9: =COUNTIFS(SessionLog!$B$2:$B$309,$A9,SessionLog!$E$2:$E$309,"SE_mysql.Votes",SessionLog!$F$2:$F$309,"D") | L9: =COUNTIFS(SessionLog!$B$2:$B$309,$A9,SessionLog!$E$2:$E$309,"SE_mysql.Votetypes",SessionLog!$F$2:$F$309,"F") | M9: =COUNTIFS(SessionLog!$B$2:$B$309,$A9,SessionLog!$E$2:$E$309,"SE_mysql.Votetypes",SessionLog!$F$2:$F$309,"D") | N9: =COUNTIFS(SessionLog!$B$2:$B$309,$A9,SessionLog!$E$2:$E$309,"SE_mongodb.Badges",SessionLog!$F$2:$F$309,"F") | O9: =COUNTIFS(SessionLog!$B$2:$B$309,$A9,SessionLog!$E$2:$E$309,"SE_mongodb.Badges",SessionLog!$F$2:$F$309,"D") | P9: =COUNTIFS(SessionLog!$B$2:$B$309,$A9,SessionLog!$E$2:$E$309,"SE_mongodb.Posts",SessionLog!$F$2:$F$309,"F") | Q9: =COUNTIFS(SessionLog!$B$2:$B$309,$A9,SessionLog!$E$2:$E$309,"SE_mongodb.Posts",SessionLog!$F$2:$F$309,"D") | R9: =COUNTIFS(SessionLog!$B$2:$B$309,$A9,SessionLog!$E$2:$E$309,"SE_mongodb.Users",SessionLog!$F$2:$F$309,"F") | S9: =COUNTIFS(SessionLog!$B$2:$B$309,$A9,SessionLog!$E$2:$E$309,"SE_mongodb.Users",SessionLog!$F$2:$F$309,"D") | T9: =COUNTIFS(SessionLog!$B$2:$B$309,$A9,SessionLog!$E$2:$E$309,"SE_mongodb.Comments",SessionLog!$F$2:$F$309,"F") | U9: =COUNTIFS(SessionLog!$B$2:$B$309,$A9,SessionLog!$E$2:$E$309,"SE_mongodb.Comments",SessionLog!$F$2:$F$309,"D") | V9: =COUNTIFS(SessionLog!$B$2:$B$309,$A9,SessionLog!$E$2:$E$309,"SE_neo4j.postlinks",SessionLog!$F$2:$F$309,"F") | W9: =COUNTIFS(SessionLog!$B$2:$B$309,$A9,SessionLog!$E$2:$E$309,"SE_neo4j.postlinks",SessionLog!$F$2:$F$309,"D") | X9: =COUNTIFS(SessionLog!$B$2:$B$309,$A9,SessionLog!$E$2:$E$309,"SE_neo4j.Posts",SessionLog!$F$2:$F$309,"F") | Y9: =COUNTIFS(SessionLog!$B$2:$B$309,$A9,SessionLog!$E$2:$E$309,"SE_neo4j.Posts",SessionLog!$F$2:$F$309,"D") | Z9: =COUNTIFS(SessionLog!$B$2:$B$309,$A9,SessionLog!$E$2:$E$309,"SE_neo4j.Comments",SessionLog!$F$2:$F$309,"F") | AA9: =COUNTIFS(SessionLog!$B$2:$B$309,$A9,SessionLog!$E$2:$E$309,"SE_neo4j.Comments",SessionLog!$F$2:$F$309,"D") | AB9: =COUNTIFS(SessionLog!$B$2:$B$309,$A9,SessionLog!$E$2:$E$309,"SE_neo4j.Users",SessionLog!$F$2:$F$309,"F") | AC9: =COUNTIFS(SessionLog!$B$2:$B$309,$A9,SessionLog!$E$2:$E$309,"SE_neo4j.Users",SessionLog!$F$2:$F$309,"D") | AD9: =COUNTIFS(SessionLog!$B$2:$B$309,$A9,SessionLog!$E$2:$E$309,"SE_neo4j.Tags",SessionLog!$F$2:$F$309,"F") | AE9: =COUNTIFS(SessionLog!$B$2:$B$309,$A9,SessionLog!$E$2:$E$309,"SE_neo4j.Tags",SessionLog!$F$2:$F$309,"D")
A10: C3 | B10: =COUNTIFS(SessionLog!$B$2:$B$309,$A10,SessionLog!$E$2:$E$309,"SE_mysql.postes",SessionLog!$F$2:$F$309,"F") | C10: =COUNTIFS(SessionLog!$B$2:$B$309,$A10,SessionLog!$E$2:$E$309,"SE_mysql.postes",SessionLog!$F$2:$F$309,"D") | D10: =COUNTIFS(SessionLog!$B$2:$B$309,$A10,SessionLog!$E$2:$E$309,"SE_mysql.Posttypes",SessionLog!$F$2:$F$309,"F") | E10: =COUNTIFS(SessionLog!$B$2:$B$309,$A10,SessionLog!$E$2:$E$309,"SE_mysql.Posttypes",SessionLog!$F$2:$F$309,"D") | F10: =COUNTIFS(SessionLog!$B$2:$B$309,$A10,SessionLog!$E$2:$E$309,"SE_mysql.Users",SessionLog!$F$2:$F$309,"F") | G10: =COUNTIFS(SessionLog!$B$2:$B$309,$A10,SessionLog!$E$2:$E$309,"SE_mysql.Users",SessionLog!$F$2:$F$309,"D") | H10: =COUNTIFS(SessionLog!$B$2:$B$309,$A10,SessionLog!$E$2:$E$309,"SE_mysql.Flagtypes",SessionLog!$F$2:$F$309,"F") | I10: =COUNTIFS(SessionLog!$B$2:$B$309,$A10,SessionLog!$E$2:$E$309,"SE_mysql.Flagtypes",SessionLog!$F$2:$F$309,"D") | J10: =COUNTIFS(SessionLog!$B$2:$B$309,$A10,SessionLog!$E$2:$E$309,"SE_mysql.Votes",SessionLog!$F$2:$F$309,"F") | K10: =COUNTIFS(SessionLog!$B$2:$B$309,$A10,SessionLog!$E$2:$E$309,"SE_mysql.Votes",SessionLog!$F$2:$F$309,"D") | L10: =COUNTIFS(SessionLog!$B$2:$B$309,$A10,SessionLog!$E$2:$E$309,"SE_mysql.Votetypes",SessionLog!$F$2:$F$309,"F") | M10: =COUNTIFS(SessionLog!$B$2:$B$309,$A10,SessionLog!$E$2:$E$309,"SE_mysql.Votetypes",SessionLog!$F$2:$F$309,"D") | N10: =COUNTIFS(SessionLog!$B$2:$B$309,$A10,SessionLog!$E$2:$E$309,"SE_mongodb.Badges",SessionLog!$F$2:$F$309,"F") | O10: =COUNTIFS(SessionLog!$B$2:$B$309,$A10,SessionLog!$E$2:$E$309,"SE_mongodb.Badges",SessionLog!$F$2:$F$309,"D") | P10: =COUNTIFS(SessionLog!$B$2:$B$309,$A10,SessionLog!$E$2:$E$309,"SE_mongodb.Posts",SessionLog!$F$2:$F$309,"F") | Q10: =COUNTIFS(SessionLog!$B$2:$B$309,$A10,SessionLog!$E$2:$E$309,"SE_mongodb.Posts",SessionLog!$F$2:$F$309,"D") | R10: =COUNTIFS(SessionLog!$B$2:$B$309,$A10,SessionLog!$E$2:$E$309,"SE_mongodb.Users",SessionLog!$F$2:$F$309,"F") | S10: =COUNTIFS(SessionLog!$B$2:$B$309,$A10,SessionLog!$E$2:$E$309,"SE_mongodb.Users",SessionLog!$F$2:$F$309,"D") | T10: =COUNTIFS(SessionLog!$B$2:$B$309,$A10,SessionLog!$E$2:$E$309,"SE_mongodb.Comments",SessionLog!$F$2:$F$309,"F") | U10: =COUNTIFS(SessionLog!$B$2:$B$309,$A10,SessionLog!$E$2:$E$309,"SE_mongodb.Comments",SessionLog!$F$2:$F$309,"D") | V10: =COUNTIFS(SessionLog!$B$2:$B$309,$A10,SessionLog!$E$2:$E$309,"SE_neo4j.postlinks",SessionLog!$F$2:$F$309,"F") | W10: =COUNTIFS(SessionLog!$B$2:$B$309,$A10,SessionLog!$E$2:$E$309,"SE_neo4j.postlinks",SessionLog!$F$2:$F$309,"D") | X10: =COUNTIFS(SessionLog!$B$2:$B$309,$A10,SessionLog!$E$2:$E$309,"SE_neo4j.Posts",SessionLog!$F$2:$F$309,"F") | Y10: =COUNTIFS(SessionLog!$B$2:$B$309,$A10,SessionLog!$E$2:$E$309,"SE_neo4j.Posts",SessionLog!$F$2:$F$309,"D") | Z10: =COUNTIFS(SessionLog!$B$2:$B$309,$A10,SessionLog!$E$2:$E$309,"SE_neo4j.Comments",SessionLog!$F$2:$F$309,"F") | AA10: =COUNTIFS(SessionLog!$B$2:$B$309,$A10,SessionLog!$E$2:$E$309,"SE_neo4j.Comments",SessionLog!$F$2:$F$309,"D") | AB10: =COUNTIFS(SessionLog!$B$2:$B$309,$A10,SessionLog!$E$2:$E$309,"SE_neo4j.Users",SessionLog!$F$2:$F$309,"F") | AC10: =COUNTIFS(SessionLog!$B$2:$B$309,$A10,SessionLog!$E$2:$E$309,"SE_neo4j.Users",SessionLog!$F$2:$F$309,"D") | AD10: =COUNTIFS(SessionLog!$B$2:$B$309,$A10,SessionLog!$E$2:$E$309,"SE_neo4j.Tags",SessionLog!$F$2:$F$309,"F") | AE10: =COUNTIFS(SessionLog!$B$2:$B$309,$A10,SessionLog!$E$2:$E$309,"SE_neo4j.Tags",SessionLog!$F$2:$F$309,"D")
A11: D1 | B11: =COUNTIFS(SessionLog!$B$2:$B$309,$A11,SessionLog!$E$2:$E$309,"SE_mysql.postes",SessionLog!$F$2:$F$309,"F") | C11: =COUNTIFS(SessionLog!$B$2:$B$309,$A11,SessionLog!$E$2:$E$309,"SE_mysql.postes",SessionLog!$F$2:$F$309,"D") | D11: =COUNTIFS(SessionLog!$B$2:$B$309,$A11,SessionLog!$E$2:$E$309,"SE_mysql.Posttypes",SessionLog!$F$2:$F$309,"F") | E11: =COUNTIFS(SessionLog!$B$2:$B$309,$A11,SessionLog!$E$2:$E$309,"SE_mysql.Posttypes",SessionLog!$F$2:$F$309,"D") | F11: =COUNTIFS(SessionLog!$B$2:$B$309,$A11,SessionLog!$E$2:$E$309,"SE_mysql.Users",SessionLog!$F$2:$F$309,"F") | G11: =COUNTIFS(SessionLog!$B$2:$B$309,$A11,SessionLog!$E$2:$E$309,"SE_mysql.Users",SessionLog!$F$2:$F$309,"D") | H11: =COUNTIFS(SessionLog!$B$2:$B$309,$A11,SessionLog!$E$2:$E$309,"SE_mysql.Flagtypes",SessionLog!$F$2:$F$309,"F") | I11: =COUNTIFS(SessionLog!$B$2:$B$309,$A11,SessionLog!$E$2:$E$309,"SE_mysql.Flagtypes",SessionLog!$F$2:$F$309,"D") | J11: =COUNTIFS(SessionLog!$B$2:$B$309,$A11,SessionLog!$E$2:$E$309,"SE_mysql.Votes",SessionLog!$F$2:$F$309,"F") | K11: =COUNTIFS(SessionLog!$B$2:$B$309,$A11,SessionLog!$E$2:$E$309,"SE_mysql.Votes",SessionLog!$F$2:$F$309,"D") | L11: =COUNTIFS(SessionLog!$B$2:$B$309,$A11,SessionLog!$E$2:$E$309,"SE_mysql.Votetypes",SessionLog!$F$2:$F$309,"F") | M11: =COUNTIFS(SessionLog!$B$2:$B$309,$A11,SessionLog!$E$2:$E$309,"SE_mysql.Votetypes",SessionLog!$F$2:$F$309,"D") | N11: =COUNTIFS(SessionLog!$B$2:$B$309,$A11,SessionLog!$E$2:$E$309,"SE_mongodb.Badges",SessionLog!$F$2:$F$309,"F") | O11: =COUNTIFS(SessionLog!$B$2:$B$309,$A11,SessionLog!$E$2:$E$309,"SE_mongodb.Badges",SessionLog!$F$2:$F$309,"D") | P11: =COUNTIFS(SessionLog!$B$2:$B$309,$A11,SessionLog!$E$2:$E$309,"SE_mongodb.Posts",SessionLog!$F$2:$F$309,"F") | Q11: =COUNTIFS(SessionLog!$B$2:$B$309,$A11,SessionLog!$E$2:$E$309,"SE_mongodb.Posts",SessionLog!$F$2:$F$309,"D") | R11: =COUNTIFS(SessionLog!$B$2:$B$309,$A11,SessionLog!$E$2:$E$309,"SE_mongodb.Users",SessionLog!$F$2:$F$309,"F") | S11: =COUNTIFS(SessionLog!$B$2:$B$309,$A11,SessionLog!$E$2:$E$309,"SE_mongodb.Users",SessionLog!$F$2:$F$309,"D") | T11: =COUNTIFS(SessionLog!$B$2:$B$309,$A11,SessionLog!$E$2:$E$309,"SE_mongodb.Comments",SessionLog!$F$2:$F$309,"F") | U11: =COUNTIFS(SessionLog!$B$2:$B$309,$A11,SessionLog!$E$2:$E$309,"SE_mongodb.Comments",SessionLog!$F$2:$F$309,"D") | V11: =COUNTIFS(SessionLog!$B$2:$B$309,$A11,SessionLog!$E$2:$E$309,"SE_neo4j.postlinks",SessionLog!$F$2:$F$309,"F") | W11: =COUNTIFS(SessionLog!$B$2:$B$309,$A11,SessionLog!$E$2:$E$309,"SE_neo4j.postlinks",SessionLog!$F$2:$F$309,"D") | X11: =COUNTIFS(SessionLog!$B$2:$B$309,$A11,SessionLog!$E$2:$E$309,"SE_neo4j.Posts",SessionLog!$F$2:$F$309,"F") | Y11: =COUNTIFS(SessionLog!$B$2:$B$309,$A11,SessionLog!$E$2:$E$309,"SE_neo4j.Posts",SessionLog!$F$2:$F$309,"D") | Z11: =COUNTIFS(SessionLog!$B$2:$B$309,$A11,SessionLog!$E$2:$E$309,"SE_neo4j.Comments",SessionLog!$F$2:$F$309,"F") | AA11: =COUNTIFS(SessionLog!$B$2:$B$309,$A11,SessionLog!$E$2:$E$309,"SE_neo4j.Comments",SessionLog!$F$2:$F$309,"D") | AB11: =COUNTIFS(SessionLog!$B$2:$B$309,$A11,SessionLog!$E$2:$E$309,"SE_neo4j.Users",SessionLog!$F$2:$F$309,"F") | AC11: =COUNTIFS(SessionLog!$B$2:$B$309,$A11,SessionLog!$E$2:$E$309,"SE_neo4j.Users",SessionLog!$F$2:$F$309,"D") | AD11: =COUNTIFS(SessionLog!$B$2:$B$309,$A11,SessionLog!$E$2:$E$309,"SE_neo4j.Tags",SessionLog!$F$2:$F$309,"F") | AE11: =COUNTIFS(SessionLog!$B$2:$B$309,$A11,SessionLog!$E$2:$E$309,"SE_neo4j.Tags",SessionLog!$F$2:$F$309,"D")
A12: D2 | B12: =COUNTIFS(SessionLog!$B$2:$B$309,$A12,SessionLog!$E$2:$E$309,"SE_mysql.postes",SessionLog!$F$2:$F$309,"F") | C12: =COUNTIFS(SessionLog!$B$2:$B$309,$A12,SessionLog!$E$2:$E$309,"SE_mysql.postes",SessionLog!$F$2:$F$309,"D") | D12: =COUNTIFS(SessionLog!$B$2:$B$309,$A12,SessionLog!$E$2:$E$309,"SE_mysql.Posttypes",SessionLog!$F$2:$F$309,"F") | E12: =COUNTIFS(SessionLog!$B$2:$B$309,$A12,SessionLog!$E$2:$E$309,"SE_mysql.Posttypes",SessionLog!$F$2:$F$309,"D") | F12: =COUNTIFS(SessionLog!$B$2:$B$309,$A12,SessionLog!$E$2:$E$309,"SE_mysql.Users",SessionLog!$F$2:$F$309,"F") | G12: =COUNTIFS(SessionLog!$B$2:$B$309,$A12,SessionLog!$E$2:$E$309,"SE_mysql.Users",SessionLog!$F$2:$F$309,"D") | H12: =COUNTIFS(SessionLog!$B$2:$B$309,$A12,SessionLog!$E$2:$E$309,"SE_mysql.Flagtypes",SessionLog!$F$2:$F$309,"F") | I12: =COUNTIFS(SessionLog!$B$2:$B$309,$A12,SessionLog!$E$2:$E$309,"SE_mysql.Flagtypes",SessionLog!$F$2:$F$309,"D") | J12: =COUNTIFS(SessionLog!$B$2:$B$309,$A12,SessionLog!$E$2:$E$309,"SE_mysql.Votes",SessionLog!$F$2:$F$309,"F") | K12: =COUNTIFS(SessionLog!$B$2:$B$309,$A12,SessionLog!$E$2:$E$309,"SE_mysql.Votes",SessionLog!$F$2:$F$309,"D") | L12: =COUNTIFS(SessionLog!$B$2:$B$309,$A12,SessionLog!$E$2:$E$309,"SE_mysql.Votetypes",SessionLog!$F$2:$F$309,"F") | M12: =COUNTIFS(SessionLog!$B$2:$B$309,$A12,SessionLog!$E$2:$E$309,"SE_mysql.Votetypes",SessionLog!$F$2:$F$309,"D") | N12: =COUNTIFS(SessionLog!$B$2:$B$309,$A12,SessionLog!$E$2:$E$309,"SE_mongodb.Badges",SessionLog!$F$2:$F$309,"F") | O12: =COUNTIFS(SessionLog!$B$2:$B$309,$A12,SessionLog!$E$2:$E$309,"SE_mongodb.Badges",SessionLog!$F$2:$F$309,"D") | P12: =COUNTIFS(SessionLog!$B$2:$B$309,$A12,SessionLog!$E$2:$E$309,"SE_mongodb.Posts",SessionLog!$F$2:$F$309,"F") | Q12: =COUNTIFS(SessionLog!$B$2:$B$309,$A12,SessionLog!$E$2:$E$309,"SE_mongodb.Posts",SessionLog!$F$2:$F$309,"D") | R12: =COUNTIFS(SessionLog!$B$2:$B$309,$A12,SessionLog!$E$2:$E$309,"SE_mongodb.Users",SessionLog!$F$2:$F$309,"F") | S12: =COUNTIFS(SessionLog!$B$2:$B$309,$A12,SessionLog!$E$2:$E$309,"SE_mongodb.Users",SessionLog!$F$2:$F$309,"D") | T12: =COUNTIFS(SessionLog!$B$2:$B$309,$A12,SessionLog!$E$2:$E$309,"SE_mongodb.Comments",SessionLog!$F$2:$F$309,"F") | U12: =COUNTIFS(SessionLog!$B$2:$B$309,$A12,SessionLog!$E$2:$E$309,"SE_mongodb.Comments",SessionLog!$F$2:$F$309,"D") | V12: =COUNTIFS(SessionLog!$B$2:$B$309,$A12,SessionLog!$E$2:$E$309,"SE_neo4j.postlinks",SessionLog!$F$2:$F$309,"F") | W12: =COUNTIFS(SessionLog!$B$2:$B$309,$A12,SessionLog!$E$2:$E$309,"SE_neo4j.postlinks",SessionLog!$F$2:$F$309,"D") | X12: =COUNTIFS(SessionLog!$B$2:$B$309,$A12,SessionLog!$E$2:$E$309,"SE_neo4j.Posts",SessionLog!$F$2:$F$309,"F") | Y12: =COUNTIFS(SessionLog!$B$2:$B$309,$A12,SessionLog!$E$2:$E$309,"SE_neo4j.Posts",SessionLog!$F$2:$F$309,"D") | Z12: =COUNTIFS(SessionLog!$B$2:$B$309,$A12,SessionLog!$E$2:$E$309,"SE_neo4j.Comments",SessionLog!$F$2:$F$309,"F") | AA12: =COUNTIFS(SessionLog!$B$2:$B$309,$A12,SessionLog!$E$2:$E$309,"SE_neo4j.Comments",SessionLog!$F$2:$F$309,"D") | AB12: =COUNTIFS(SessionLog!$B$2:$B$309,$A12,SessionLog!$E$2:$E$309,"SE_neo4j.Users",SessionLog!$F$2:$F$309,"F") | AC12: =COUNTIFS(SessionLog!$B$2:$B$309,$A12,SessionLog!$E$2:$E$309,"SE_neo4j.Users",SessionLog!$F$2:$F$309,"D") | AD12: =COUNTIFS(SessionLog!$B$2:$B$309,$A12,SessionLog!$E$2:$E$309,"SE_neo4j.Tags",SessionLog!$F$2:$F$309,"F") | AE12: =COUNTIFS(SessionLog!$B$2:$B$309,$A12,SessionLog!$E$2:$E$309,"SE_neo4j.Tags",SessionLog!$F$2:$F$309,"D")
A13: E1 | B13: =COUNTIFS(SessionLog!$B$2:$B$309,$A13,SessionLog!$E$2:$E$309,"SE_mysql.postes",SessionLog!$F$2:$F$309,"F") | C13: =COUNTIFS(SessionLog!$B$2:$B$309,$A13,SessionLog!$E$2:$E$309,"SE_mysql.postes",SessionLog!$F$2:$F$309,"D") | D13: =COUNTIFS(SessionLog!$B$2:$B$309,$A13,SessionLog!$E$2:$E$309,"SE_mysql.Posttypes",SessionLog!$F$2:$F$309,"F") | E13: =COUNTIFS(SessionLog!$B$2:$B$309,$A13,SessionLog!$E$2:$E$309,"SE_mysql.Posttypes",SessionLog!$F$2:$F$309,"D") | F13: =COUNTIFS(SessionLog!$B$2:$B$309,$A13,SessionLog!$E$2:$E$309,"SE_mysql.Users",SessionLog!$F$2:$F$309,"F") | G13: =COUNTIFS(SessionLog!$B$2:$B$309,$A13,SessionLog!$E$2:$E$309,"SE_mysql.Users",SessionLog!$F$2:$F$309,"D") | H13: =COUNTIFS(SessionLog!$B$2:$B$309,$A13,SessionLog!$E$2:$E$309,"SE_mysql.Flagtypes",SessionLog!$F$2:$F$309,"F") | I13: =COUNTIFS(SessionLog!$B$2:$B$309,$A13,SessionLog!$E$2:$E$309,"SE_mysql.Flagtypes",SessionLog!$F$2:$F$309,"D") | J13: =COUNTIFS(SessionLog!$B$2:$B$309,$A13,SessionLog!$E$2:$E$309,"SE_mysql.Votes",SessionLog!$F$2:$F$309,"F") | K13: =COUNTIFS(SessionLog!$B$2:$B$309,$A13,SessionLog!$E$2:$E$309,"SE_mysql.Votes",SessionLog!$F$2:$F$309,"D") | L13: =COUNTIFS(SessionLog!$B$2:$B$309,$A13,SessionLog!$E$2:$E$309,"SE_mysql.Votetypes",SessionLog!$F$2:$F$309,"F") | M13: =COUNTIFS(SessionLog!$B$2:$B$309,$A13,SessionLog!$E$2:$E$309,"SE_mysql.Votetypes",SessionLog!$F$2:$F$309,"D") | N13: =COUNTIFS(SessionLog!$B$2:$B$309,$A13,SessionLog!$E$2:$E$309,"SE_mongodb.Badges",SessionLog!$F$2:$F$309,"F") | O13: =COUNTIFS(SessionLog!$B$2:$B$309,$A13,SessionLog!$E$2:$E$309,"SE_mongodb.Badges",SessionLog!$F$2:$F$309,"D") | P13: =COUNTIFS(SessionLog!$B$2:$B$309,$A13,SessionLog!$E$2:$E$309,"SE_mongodb.Posts",SessionLog!$F$2:$F$309,"F") | Q13: =COUNTIFS(SessionLog!$B$2:$B$309,$A13,SessionLog!$E$2:$E$309,"SE_mongodb.Posts",SessionLog!$F$2:$F$309,"D") | R13: =COUNTIFS(SessionLog!$B$2:$B$309,$A13,SessionLog!$E$2:$E$309,"SE_mongodb.Users",SessionLog!$F$2:$F$309,"F") | S13: =COUNTIFS(SessionLog!$B$2:$B$309,$A13,SessionLog!$E$2:$E$309,"SE_mongodb.Users",SessionLog!$F$2:$F$309,"D") | T13: =COUNTIFS(SessionLog!$B$2:$B$309,$A13,SessionLog!$E$2:$E$309,"SE_mongodb.Comments",SessionLog!$F$2:$F$309,"F") | U13: =COUNTIFS(SessionLog!$B$2:$B$309,$A13,SessionLog!$E$2:$E$309,"SE_mongodb.Comments",SessionLog!$F$2:$F$309,"D") | V13: =COUNTIFS(SessionLog!$B$2:$B$309,$A13,SessionLog!$E$2:$E$309,"SE_neo4j.postlinks",SessionLog!$F$2:$F$309,"F") | W13: =COUNTIFS(SessionLog!$B$2:$B$309,$A13,SessionLog!$E$2:$E$309,"SE_neo4j.postlinks",SessionLog!$F$2:$F$309,"D") | X13: =COUNTIFS(SessionLog!$B$2:$B$309,$A13,SessionLog!$E$2:$E$309,"SE_neo4j.Posts",SessionLog!$F$2:$F$309,"F") | Y13: =COUNTIFS(SessionLog!$B$2:$B$309,$A13,SessionLog!$E$2:$E$309,"SE_neo4j.Posts",SessionLog!$F$2:$F$309,"D") | Z13: =COUNTIFS(SessionLog!$B$2:$B$309,$A13,SessionLog!$E$2:$E$309,"SE_neo4j.Comments",SessionLog!$F$2:$F$309,"F") | AA13: =COUNTIFS(SessionLog!$B$2:$B$309,$A13,SessionLog!$E$2:$E$309,"SE_neo4j.Comments",SessionLog!$F$2:$F$309,"D") | AB13: =COUNTIFS(SessionLog!$B$2:$B$309,$A13,SessionLog!$E$2:$E$309,"SE_neo4j.Users",SessionLog!$F$2:$F$309,"F") | AC13: =COUNTIFS(SessionLog!$B$2:$B$309,$A13,SessionLog!$E$2:$E$309,"SE_neo4j.Users",SessionLog!$F$2:$F$309,"D") | AD13: =COUNTIFS(SessionLog!$B$2:$B$309,$A13,SessionLog!$E$2:$E$309,"SE_neo4j.Tags",SessionLog!$F$2:$F$309,"F") | AE13: =COUNTIFS(SessionLog!$B$2:$B$309,$A13,SessionLog!$E$2:$E$309,"SE_neo4j.Tags",SessionLog!$F$2:$F$309,"D")
... A18: COLD2 | B18: =COUNTIFS(SessionLog!$B$2:$B$309,$A18,SessionLog!$E$2:$E$309,"SE_mysql.postes",SessionLog!$F$2:$F$309,"F") | C18: =COUNTIFS(SessionLog!$B$2:$B$309,$A18,SessionLog!$E$2:$E$309,"SE_mysql.postes",SessionLog!$F$2:$F$309,"D") | D18: =COUNTIFS(SessionLog!$B$2:$B$309,$A18,SessionLog!$E$2:$E$309,"SE_mysql.Posttypes",SessionLog!$F$2:$F$309,"F") | E18: =COUNTIFS(SessionLog!$B$2:$B$309,$A18,SessionLog!$E$2:$E$309,"SE_mysql.Posttypes",SessionLog!$F$2:$F$309,"D") | F18: =COUNTIFS(SessionLog!$B$2:$B$309,$A18,SessionLog!$E$2:$E$309,"SE_mysql.Users",SessionLog!$F$2:$F$309,"F") | G18: =COUNTIFS(SessionLog!$B$2:$B$309,$A18,SessionLog!$E$2:$E$309,"SE_mysql.Users",SessionLog!$F$2:$F$309,"D") | H18: =COUNTIFS(SessionLog!$B$2:$B$309,$A18,SessionLog!$E$2:$E$309,"SE_mysql.Flagtypes",SessionLog!$F$2:$F$309,"F") | I18: =COUNTIFS(SessionLog!$B$2:$B$309,$A18,SessionLog!$E$2:$E$309,"SE_mysql.Flagtypes",SessionLog!$F$2:$F$309,"D") | J18: =COUNTIFS(SessionLog!$B$2:$B$309,$A18,SessionLog!$E$2:$E$309,"SE_mysql.Votes",SessionLog!$F$2:$F$309,"F") | K18: =COUNTIFS(SessionLog!$B$2:$B$309,$A18,SessionLog!$E$2:$E$309,"SE_mysql.Votes",SessionLog!$F$2:$F$309,"D") | L18: =COUNTIFS(SessionLog!$B$2:$B$309,$A18,SessionLog!$E$2:$E$309,"SE_mysql.Votetypes",SessionLog!$F$2:$F$309,"F") | M18: =COUNTIFS(SessionLog!$B$2:$B$309,$A18,SessionLog!$E$2:$E$309,"SE_mysql.Votetypes",SessionLog!$F$2:$F$309,"D") | N18: =COUNTIFS(SessionLog!$B$2:$B$309,$A18,SessionLog!$E$2:$E$309,"SE_mongodb.Badges",SessionLog!$F$2:$F$309,"F") | O18: =COUNTIFS(SessionLog!$B$2:$B$309,$A18,SessionLog!$E$2:$E$309,"SE_mongodb.Badges",SessionLog!$F$2:$F$309,"D") | P18: =COUNTIFS(SessionLog!$B$2:$B$309,$A18,SessionLog!$E$2:$E$309,"SE_mongodb.Posts",SessionLog!$F$2:$F$309,"F") | Q18: =COUNTIFS(SessionLog!$B$2:$B$309,$A18,SessionLog!$E$2:$E$309,"SE_mongodb.Posts",SessionLog!$F$2:$F$309,"D") | R18: =COUNTIFS(SessionLog!$B$2:$B$309,$A18,SessionLog!$E$2:$E$309,"SE_mongodb.Users",SessionLog!$F$2:$F$309,"F") | S18: =COUNTIFS(SessionLog!$B$2:$B$309,$A18,SessionLog!$E$2:$E$309,"SE_mongodb.Users",SessionLog!$F$2:$F$309,"D") | T18: =COUNTIFS(SessionLog!$B$2:$B$309,$A18,SessionLog!$E$2:$E$309,"SE_mongodb.Comments",SessionLog!$F$2:$F$309,"F") | U18: =COUNTIFS(SessionLog!$B$2:$B$309,$A18,SessionLog!$E$2:$E$309,"SE_mongodb.Comments",SessionLog!$F$2:$F$309,"D") | V18: =COUNTIFS(SessionLog!$B$2:$B$309,$A18,SessionLog!$E$2:$E$309,"SE_neo4j.postlinks",SessionLog!$F$2:$F$309,"F") | W18: =COUNTIFS(SessionLog!$B$2:$B$309,$A18,SessionLog!$E$2:$E$309,"SE_neo4j.postlinks",SessionLog!$F$2:$F$309,"D") | X18: =COUNTIFS(SessionLog!$B$2:$B$309,$A18,SessionLog!$E$2:$E$309,"SE_neo4j.Posts",SessionLog!$F$2:$F$309,"F") | Y18: =COUNTIFS(SessionLog!$B$2:$B$309,$A18,SessionLog!$E$2:$E$309,"SE_neo4j.Posts",SessionLog!$F$2:$F$309,"D") | Z18: =COUNTIFS(SessionLog!$B$2:$B$309,$A18,SessionLog!$E$2:$E$309,"SE_neo4j.Comments",SessionLog!$F$2:$F$309,"F") | AA18: =COUNTIFS(SessionLog!$B$2:$B$309,$A18,SessionLog!$E$2:$E$309,"SE_neo4j.Comments",SessionLog!$F$2:$F$309,"D") | AB18: =COUNTIFS(SessionLog!$B$2:$B$309,$A18,SessionLog!$E$2:$E$309,"SE_neo4j.Users",SessionLog!$F$2:$F$309,"F") | AC18: =COUNTIFS(SessionLog!$B$2:$B$309,$A18,SessionLog!$E$2:$E$309,"SE_neo4j.Users",SessionLog!$F$2:$F$309,"D") | AD18: =COUNTIFS(SessionLog!$B$2:$B$309,$A18,SessionLog!$E$2:$E$309,"SE_neo4j.Tags",SessionLog!$F$2:$F$309,"F") | AE18: =COUNTIFS(SessionLog!$B$2:$B$309,$A18,SessionLog!$E$2:$E$309,"SE_neo4j.Tags",SessionLog!$F$2:$F$309,"D")

Sheet Attributs
A1: Analyste | B1: SE_mysql.postes.Id (M) | C1: SE_mysql.postes.Id (P) | D1: SE_mysql.postes.PostTypeId (M) | E1: SE_mysql.postes.PostTypeId (P) | F1: SE_mysql.postes.Title (M) | G1: SE_mysql.postes.Title (P) | H1: SE_mysql.postes.OwnerUserId (M) | I1: SE_mysql.postes.OwnerUserId (P) | J1: SE_mysql.postes.ViewCount (M) | K1: SE_mysql.postes.ViewCount (P) | L1: SE_mysql.postes.LastEditDate (M) | M1: SE_mysql.postes.LastEditDate (P) | N1: SE_mysql.postes.LastEditorUserId (M) | O1: SE_mysql.postes.LastEditorUserId (P) | P1: SE_mysql.postes.CreationDate (M) | Q1: SE_mysql.postes.CreationDate (P) | R1: SE_mysql.Posttypes.Id (M) | S1: SE_mysql.Posttypes.Id (P) | T1: SE_mysql.Posttypes.Name (M) | U1: SE_mysql.Posttypes.Name (P) | V1: SE_mysql.Users.Id (M) | W1: SE_mysql.Users.Id (P) | X1: SE_mysql.Users.Views (M) | Y1: SE_mysql.Users.Views (P) | Z1: SE_mysql.Users.UpVotes (M) | AA1: SE_mysql.Users.UpVotes (P) | AB1: SE_mysql.Users.DisplayName (M) | AC1: SE_mysql.Users.DisplayName (P) | AD1: SE_mysql.Users.DownVotes (M) | AE1: SE_mysql.Users.DownVotes (P) | AF1: SE_mysql.Users.LastAccessDate (M) | AG1: SE_mysql.Users.LastAccessDate (P) | AH1: SE_mysql.Users.Reputation (M) | AI1: SE_mysql.Users.Reputation (P) | AJ1: SE_mysql.Flagtypes.Id (M) | AK1: SE_mysql.Flagtypes.Id (P) | AL1: SE_mysql.Flagtypes.Name (M) | AM1: SE_mysql.Flagtypes.Name (P) | AN1: SE_mysql.Votes.Id (M) | AO1: SE_mysql.Votes.Id (P) | AP1: SE_mysql.Votes.UserId (M) | AQ1: SE_mysql.Votes.UserId (P) | AR1: SE_mysql.Votes.BountyAmount (M) | AS1: SE_mysql.Votes.BountyAmount (P) | AT1: SE_mysql.Votes.CreationDate (M) | AU1: SE_mysql.Votes.CreationDate (P) | AV1: SE_mysql.Votes.PostId (M) | AW1: SE_mysql.Votes.PostId (P) | AX1: SE_mysql.Votes.VoteTypeId (M) | AY1: SE_mysql.Votes.VoteTypeId (P) | AZ1: SE_mysql.Votetypes.Id (M) | BA1: SE_mysql.Votetypes.Id (P) | BB1: SE_mysql.Votetypes.Name (M) | BC1: SE_mysql.Votetypes.Name (P) | BD1: SE_mongodb.Badges.Id (M) | BE1: SE_mongodb.Badges.Id (P) | BF1: SE_mongodb.Badges.UserId (M) | BG1: SE_mongodb.Badges.UserId (P) | BH1: SE_mongodb.Badges.Name (M) | BI1: SE_mongodb.Badges.Name (P) | BJ1: SE_mongodb.Badges.Date (M) | BK1: SE_mongodb.Badges.Date (P) | BL1: SE_mongodb.Posts.Id (M) | BM1: SE_mongodb.Posts.Id (P) | BN1: SE_mongodb.Posts.Tags (M) | BO1: SE_mongodb.Posts.Tags (P) | BP1: SE_mongodb.Posts.Body (M) | BQ1: SE_mongodb.Posts.Body (P) | BR1: SE_mongodb.Users.Id (M) | BS1: SE_mongodb.Users.Id (P) | BT1: SE_mongodb.Users.DisplayName (M) | BU1: SE_mongodb.Users.DisplayName (P) | BV1: SE_mongodb.Users.AboutMe (M) | BW1: SE_mongodb.Users.AboutMe (P) | BX1: SE_mongodb.Comments.Id (M) | BY1: SE_mongodb.Comments.Id (P) | BZ1: SE_mongodb.Comments.UserId (M) | CA1: SE_mongodb.Comments.UserId (P) | CB1: SE_mongodb.Comments.Text (M) | CC1: SE_mongodb.Comments.Text (P) | CD1: SE_mongodb.Comments.PostId (M) | CE1: SE_mongodb.Comments.PostId (P) | CF1: SE_neo4j.postlinks.id (M) | CG1: SE_neo4j.postlinks.id (P) | CH1: SE_neo4j.postlinks.LinkTypeId (M) | CI1: SE_neo4j.postlinks.LinkTypeId (P) | CJ1: SE_neo4j.postlinks.RelatedPostId (M) | CK1: SE_neo4j.postlinks.RelatedPostId (P) | CL1: SE_neo4j.postlinks.PostIdd (M) | CM1: SE_neo4j.postlinks.PostIdd (P) | CN1: SE_neo4j.postlinks.CreationDate (M) | CO1: SE_neo4j.postlinks.CreationDate (P) | CP1: SE_neo4j.Posts.id (M) | CQ1: SE_neo4j.Posts.id (P) | CR1: SE_neo4j.Posts.posttypeid (M) | CS1: SE_neo4j.Posts.posttypeid (P) | CT1: SE_neo4j.Posts.parentid (M) | CU1: SE_neo4j.Posts.parentid (P) | CV1: SE_neo4j.Posts.owneruserid (M) | CW1: SE_neo4j.Posts.owneruserid (P) | CX1: SE_neo4j.Posts.acceptedanswerid (M) | CY1: SE_neo4j.Posts.acceptedanswerid (P) | CZ1: SE_neo4j.Comments.id (M) | DA1: SE_neo4j.Comments.id (P) | DB1: SE_neo4j.Comments.creationdate (M) | DC1: SE_neo4j.Comments.creationdate (P) | DD1: SE_neo4j.Comments.score (M) | DE1: SE_neo4j.Comments.score (P) | DF1: SE_neo4j.Users.id (M) | DG1: SE_neo4j.Users.id (P) | DH1: SE_neo4j.Users.accountid (M) | DI1: SE_neo4j.Users.accountid (P) | DJ1: SE_neo4j.Users.displayname (M) | DK1: SE_neo4j.Users.displayname (P) | DL1: SE_neo4j.Users.creationdate (M) | DM1: SE_neo4j.Users.creationdate (P) | DN1: SE_neo4j.Tags.id (M) | DO1: SE_neo4j.Tags.id (P) | DP1: SE_neo4j.Tags.count (M) | DQ1: SE_neo4j.Tags.count (P) | DR1: SE_neo4j.Tags.wikipostid (M) | DS1: SE_neo4j.Tags.wikipostid (P) | DT1: SE_neo4j.Tags.tagname (M) | DU1: SE_neo4j.Tags.tagname (P) | DV1: SE_neo4j.Tags.excerptpostid (M) | DW1: SE_neo4j.Tags.excerptpostid (P)
